<ns0:entry xmlns:ns0="http://www.w3.org/2005/Atom" xmlns:ns1="http://schemas.google.com/g/2005" xmlns:ns2="http://schemas.google.com/projecthosting/issues/2009" ns1:etag="W/&quot;DkMDR347eCl7ImA9WhJWEE0.&quot;">
		<ns0:id>http://code.google.com/feeds/issues/p/nativeclient/issues/2948/comments/full/10</ns0:id><ns0:author>
			<ns0:name>bugdro...@chromium.org</ns0:name><ns0:uri>/u/101788990881243245974/</ns0:uri></ns0:author><ns0:content type="html">The following revision refers to this bug:
    http://src.chromium.org/viewvc/native_client?view=rev&amp;revision=9474

------------------------------------------------------------------------
r9474 | mseaborn@chromium.org | 2012-08-15T04:15:07.403880Z

Changed paths:
   M http://src.chromium.org/viewvc/native_client/trunk/src/native_client/tests/debug_stub/debug_stub_test.py?r1=9474&amp;r2=9473&amp;pathrev=9474

Debug stub test: Ignore "Access denied" error from terminating sel_ldr

Windows produces this error if you try to kill a process that has
already exited.

We saw this error occur on the bots on Windows in debug_stub_test.py.
This error might be obscuring the cause of a real test failure, if
sel_ldr is crashing, or it might be making the test fail when it would
otherwise pass.

Also reduce duplicated code by using the "with" syntax.

BUG=http://code.google.com/p/nativeclient/issues/detail?id=2948
TEST=run_debug_stub_test

Review URL: https://chromiumcodereview.appspot.com/10854147
------------------------------------------------------------------------</ns0:content><ns0:updated>2012-08-15T04:21:16.000Z</ns0:updated><ns0:published>2012-08-15T04:21:16.000Z</ns0:published><ns2:updates /><ns0:title>Comment 10 by bugdro...@chromium.org</ns0:title><ns0:link href="http://code.google.com/p/nativeclient/issues/detail?id=2948#c10" rel="alternate" type="text/html" /><ns0:link href="https://code.google.com/feeds/issues/p/nativeclient/issues/2948/comments/full/10" rel="self" type="application/atom+xml" /></ns0:entry>