<ns0:entry xmlns:ns0="http://www.w3.org/2005/Atom" xmlns:ns1="http://schemas.google.com/g/2005" xmlns:ns2="http://schemas.google.com/projecthosting/issues/2009" ns1:etag="W/&quot;DUYGQ347eCl7ImA9WhdTF0U.&quot;">
		<ns0:id>http://code.google.com/feeds/issues/p/nativeclient/issues/2034/comments/full/3</ns0:id><ns0:author>
			<ns0:name>ncb...@google.com</ns0:name><ns0:uri>/u/100032148147647801554/</ns0:uri></ns0:author><ns0:content type="html">After checking out the right versions, I verified that the PyAuto reload test did not crash.  However, when I added diable_dynamic_plugin_loading=1 to the command line (like the integration bots would) it did in fact crash.  The assert appears to be in a code path that is not used when the plugin is loaded via the command line.  (Or it is a sandboxing issue.  Either way, the effect is the same.)  This means that if we were running PyAuto on the integration bots, this bug would have been caught.  As such, I am marking this as a duplicate of 1917.  Getting PyAuto running on the integration bots will cover this hole in our tests.
</ns0:content><ns0:updated>2011-07-16T03:32:02.000Z</ns0:updated><ns0:published>2011-07-16T03:32:02.000Z</ns0:published><ns2:updates>
			<ns2:status>Duplicate</ns2:status><ns2:ownerUpdate>ncb...@google.com</ns2:ownerUpdate><ns2:mergedIntoUpdate>1917</ns2:mergedIntoUpdate></ns2:updates><ns0:title>Comment 3 by ncb...@google.com</ns0:title><ns0:link href="http://code.google.com/p/nativeclient/issues/detail?id=2034#c3" rel="alternate" type="text/html" /><ns0:link href="https://code.google.com/feeds/issues/p/nativeclient/issues/2034/comments/full/3" rel="self" type="application/atom+xml" /></ns0:entry>